"""Test the self-test functionality.

Self-tests are not unit tests -- they are executed at runtime on a
specific installation. They verify that that installation is properly
configured, not that the code is correct.
"""
from nose.tools import (
    eq_,
    set_trace,
)

import datetime

from . import DatabaseTest

from selftest import (
    SelfTestResult,
    HasSelfTests,
)

from util.http import IntegrationException

class TestSelfTestResult(object):

    now = datetime.datetime.utcnow()
    future = now + datetime.timedelta(seconds=5)

    def test_success_representation(self):
        """Show the string and dictionary representations of a successful
        test result.
        """
        # A successful result
        result = SelfTestResult("success1")
        result.start = self.now
        result.end = self.future
        result.result = "The result"
        result.success = True
        eq_(
            "<SelfTestResult: name='success1' duration=5.00sec success=True result='The result'>",
            repr(result)
        )

        d = result.to_dict
        eq_("success1", d['name'])
        eq_("The result", d['result'])
        eq_(5.0, d['duration'])
        eq_(True, d['success'])
        eq_(None, d['exception'])

    def test_repr_failure(self):
        """Show the string representation of a failed test result."""

        exception = IntegrationException("basic info", "debug info")

        result = SelfTestResult("failure1")
        result.start = self.now
        result.end = self.future
        result.exception = exception
        result.result = "The result"
        eq_(
            "<SelfTestResult: name='failure1' duration=5.00sec success=False exception='basic info' debug='debug info' result='The result'>",
            repr(result)
        )

        d = result.to_dict
        eq_("failure1", d['name'])
        eq_("The result", d['result'])
        eq_(5.0, d['duration'])
        eq_(False, d['success'])
        eq_('IntegrationException', d['exception']['class'])
        eq_('basic info', d['exception']['message'])
        eq_('debug info', d['exception']['debug_message'])


class TestHasSelfTests(DatabaseTest):

    def test_run_self_tests(self):
        """See what might happen when run_self_tests tries to instantiate an
        object and run its self-tests.
        """

        class Tester(HasSelfTests):
            def __init__(self, extra_arg=None):
                """This constructor works."""
                self.invoked_with = (extra_arg)

            @classmethod
            def good_alternate_constructor(self, another_extra_arg=None):
                """This alternate constructor works."""
                tester = Tester()
                tester.another_extra_arg = another_extra_arg
                return tester

            @classmethod
            def bad_alternate_constructor(self):
                """This constructor doesn't work."""
                raise Exception("I don't work!")

            def external_integration(self, _db):
                """This integration will be used to store the test results."""
                return self.integration

            def _run_self_tests(self, _db):
                self._run_self_tests_called_with = _db
                return [SelfTestResult("a test result")]
        mock_db = object()

        # This integration will be used to store the test results.
        integration = self._external_integration(self._str)
        Tester.integration = integration

        # By default, the default constructor is instantiated and its
        # _run_self_tests method is called.
        data, [setup, test] = Tester.run_self_tests(
            mock_db, extra_arg="a value"
        )
        eq_(mock_db, setup.result._run_self_tests_called_with)

        # There are two results -- `setup` from the initial setup
        # and `test` from the _run_self_tests call.
        eq_("Initial setup.", setup.name)
        eq_(True, setup.success)
        eq_("a value", setup.result.invoked_with)
        eq_("a test result", test.name)

        # The `data` variable contains a dictionary describing the test
        # suite as a whole.
        assert data['duration'] < 1
        for key in 'start', 'end':
            assert key in data

        # `data['results']` contains dictionary versions of the self-tests
        # that were returned separately.
        r1, r2 = data['results']
        eq_(r1, setup.to_dict)
        eq_(r2, test.to_dict)

        # A JSON version of `data` is stored in the
        # ExternalIntegration returned by the external_integration()
        # method.
        [result_setting] = integration.settings
        eq_(HasSelfTests.SELF_TEST_RESULTS_SETTING, result_setting.key)
        eq_(data, result_setting.json_value)

        # Remove the testing integration to show what happens when
        # HasSelfTests doesn't support the storage of test results.
        Tester.integration = None
        result_setting.value = "this value will not be changed"

        # You can specify a different class method to use as the
        # constructor. Once the object is instantiated, the same basic
        # code runs.
        data, [setup, test] = Tester.run_self_tests(
            mock_db, Tester.good_alternate_constructor,
            another_extra_arg="another value"
        )
        eq_("Initial setup.", setup.name)
        eq_(True, setup.success)
        eq_(None, setup.result.invoked_with)
        eq_("another value", setup.result.another_extra_arg)
        eq_("a test result", test.name)

        # Since the HasSelfTests object no longer has an associated
        # ExternalIntegration, the test results are not persisted
        # anywhere.
        eq_("this value will not be changed", result_setting.value)

        # If there's an exception in the constructor, the result is a
        # single SelfTestResult describing that failure. Since there is
        # no instance, _run_self_tests can't be called.
        data, [result] = Tester.run_self_tests(
            mock_db, Tester.bad_alternate_constructor,
        )
        assert isinstance(result, SelfTestResult)
        eq_(False, result.success)
        eq_("I don't work!", result.exception.message)

    def test_exception_in_has_self_tests(self):
        """An exception raised in has_self_tests itself is converted into a
        test failure.
        """
        class Tester(HasSelfTests):
            def _run_self_tests(self, _db):
                yield SelfTestResult("everything's ok so far")
                raise Exception("oh no")
                yield SelfTestResult("i'll never be called.")

        status, [init, success, failure] = Tester.run_self_tests(object())
        eq_("Initial setup.", init.name)
        eq_("everything's ok so far", success.name)

        eq_("Uncaught exception in the self-test method itself.", failure.name)
        eq_(False, failure.success)
        # The Exception was turned into an IntegrationException so that
        # its traceback could be included as debug_message.
        assert isinstance(failure.exception, IntegrationException)
        eq_("oh no", failure.exception.message)
        assert failure.exception.debug_message.startswith("Traceback")

    def test_run_test_success(self):
        o = HasSelfTests()
        # This self-test method will succeed.
        def successful_test(arg, kwarg):
            return arg, kwarg
        result = o.run_test(
            "A successful test", successful_test, "arg1", kwarg="arg2"
        )
        eq_(True, result.success)
        eq_("A successful test", result.name)
        eq_(("arg1", "arg2"), result.result)
        assert (result.end-result.start).total_seconds() < 1

    def test_run_test_failure(self):
        o = HasSelfTests()
        # This self-test method will fail.
        def unsuccessful_test(arg, kwarg):
            raise IntegrationException(arg, kwarg)
        result = o.run_test(
            "An unsuccessful test", unsuccessful_test, "arg1", kwarg="arg2"
        )
        eq_(False, result.success)
        eq_("An unsuccessful test", result.name)
        eq_(None, result.result)
        eq_("arg1", result.exception.message)
        eq_("arg2", result.exception.debug_message)
        assert (result.end-result.start).total_seconds() < 1

    def test_test_failure(self):
        o = HasSelfTests()

        # You can pass in an Exception...
        exception = Exception("argh")
        now = datetime.datetime.utcnow()
        result = o.test_failure("a failure", exception)

        # ...which will be turned into an IntegrationException.
        eq_("a failure", result.name)
        assert isinstance(result.exception, IntegrationException)
        eq_("argh", result.exception.message)
        assert (result.start-now).total_seconds() < 1

        # ... or you can pass in arguments to an IntegrationException
        result = o.test_failure("another failure", "message", "debug")
        assert isinstance(result.exception, IntegrationException)
        eq_("message", result.exception.message)
        eq_("debug", result.exception.debug_message)

        # Since no test code actually ran, the end time is the
        # same as the start time.
        eq_(result.start, result.end)
